Workbook

Sheet data
A1: source_target | B1: source_thematic_area | C1: source_target_subtheme | D1: source_target_content | E1: impact_target | F1: impact_thematic_area | G1: impact_target_subtheme | H1: impact_target_content | I1: impact_type | J1: impact_color | K1: impact_weight | L1: LLM_justification | M1: expert_comments | N1: expert | O1: expert_confidence_level
A2: TA2.41 | B2: TA2 - Clean, affordable and secure energy | C2: Energy Efficiency | D2: Member States are required to achieve cumulative end-use energy savings from 2021 to 2030, equivalent to new annual savings of at least 0.8% of final energy consumption in 2021-2023, at least 1.3% in 2024-2025, 1.5% in 2026-2027 and 1.9% in 2028-2030 | E2: TA3.3 | F2: TA3 - Industrial strategy for a clean and circular economy | G2: Circularity/Recycling | H2: Double EUcircular material use rate in the coming decade | I2: + | J2: #1FA139 | K2: 2 | L2: The implementation of TA2.41, which aims to achieve cumulative end-use energy savings, may reinforce TA3.3, which aims to double the EU's circular material use rate, as increased energy efficiency can lead to reduced material consumption and waste generation, thus supporting the transition to a more circular economy. | N2: Castellazzi Luca | O2: 8
A3: TA2.22 | B3: TA2 - Clean, affordable and secure energy | C3: Energy Efficiency | D3: Member States shall collectively ensure a reduction of energy consumption of at least 11.7% in 2030 compared to the projections of the 2020 EU Reference Scenario | E3: TA1.3 | F3: TA1 - Climate ambition | G3: GHG Reduction | H3: Reduce by at least 55% net GHG emissions compared to 1990 levels, by 2030 | I3: + | J3: #1FA139 | K3: 3 | L3: The implementation of TA2.22 may help the achievement of TA1.3, as reducing energy consumption may not be sufficient to achieve the GHG emissions reduction target. | M3: The implementation of TA2.22 will strongly contribute to the achievement of TA1.3 | N3: Castellazzi Luca | O3: 8
A4: TA2.41 | B4: TA2 - Clean, affordable and secure energy | C4: Energy Efficiency | D4: Member States are required to achieve cumulative end-use energy savings from 2021 to 2030, equivalent to new annual savings of at least 0.8% of final energy consumption in 2021-2023, at least 1.3% in 2024-2025, 1.5% in 2026-2027 and 1.9% in 2028-2030 | E4: TA1.3 | F4: TA1 - Climate ambition | G4: GHG Reduction | H4: Reduce by at least 55% net GHG emissions compared to 1990 levels, by 2030 | I4: + | J4: #1FA139 | K4: 2 | L4: The implementation of TA2.41 may help the achievement of TA1.3, as increasing energy savings may lead to increased energy demand, which could hinder the reduction of GHG emissions. | N4: Castellazzi Luca | O4: 8
A5: TA2.22 | B5: TA2 - Clean, affordable and secure energy | C5: Energy Efficiency | D5: Member States shall collectively ensure a reduction of energy consumption of at least 11.7% in 2030 compared to the projections of the 2020 EU Reference Scenario | E5: TA5.11 | F5: TA5 - Greening the Common Agricultural Policy - Farm to Fork Strategy | G5: Biodiversity Protection & Conservation | H5: Biodiversity conservation and restoration of natural resources: Protect the environment and restore natural resources. Preserve biodiversity and reduce biodiversity loss. | I5: + | J5: #1FA139 | K5: 2 | L5: The collective effort to reduce energy consumption, as stated in TA2.22, can reinforce the objectives of TA5.11 by decreasing the EU's energy footprint, promoting sustainable food production, and conserving biodiversity. | N5: Castellazzi Luca | O5: 8
A6: TA2.41 | B6: TA2 - Clean, affordable and secure energy | C6: Energy Efficiency | D6: Member States are required to achieve cumulative end-use energy savings from 2021 to 2030, equivalent to new annual savings of at least 0.8% of final energy consumption in 2021-2023, at least 1.3% in 2024-2025, 1.5% in 2026-2027 and 1.9% in 2028-2030 | E6: TA5.11 | F6: TA5 - Greening the Common Agricultural Policy - Farm to Fork Strategy | G6: Biodiversity Protection & Conservation | H6: Biodiversity conservation and restoration of natural resources: Protect the environment and restore natural resources. Preserve biodiversity and reduce biodiversity loss. | I6: + | J6: #1FA139 | K6: 2 | L6: The implementation of TA2.41, which aims to achieve cumulative end-use energy savings, can positively impact TA5.11 by reducing energy consumption and promoting sustainable practices in the food system, thus supporting biodiversity conservation and restoration of natural resources. | N6: Castellazzi Luca | O6: 8
A7: TA2.41 | B7: TA2 - Clean, affordable and secure energy | C7: Energy Efficiency | D7: Member States are required to achieve cumulative end-use energy savings from 2021 to 2030, equivalent to new annual savings of at least 0.8% of final energy consumption in 2021-2023, at least 1.3% in 2024-2025, 1.5% in 2026-2027 and 1.9% in 2028-2030 | E7: TA6.1 | F7: TA6 - Preserving and protecting biodiversity | G7: Biodiversity Protection & Conservation | H7: 1.a Legally protect a minimum of 30% of the EU land area | I7: + | J7: #1FA139 | K7: 2 | L7: The implementation of TA2.41, which aims to achieve cumulative end-use energy savings, may reinforce TA6.1 by promoting the protection of at least 30% of the EU's land area, as the reduction of energy consumption can lead to lower land-use pressures and help preserve natural habitats. | N7: Castellazzi Luca | O7: 8
A8: TA2.41 | B8: TA2 - Clean, affordable and secure energy | C8: Energy Efficiency | D8: Member States are required to achieve cumulative end-use energy savings from 2021 to 2030, equivalent to new annual savings of at least 0.8% of final energy consumption in 2021-2023, at least 1.3% in 2024-2025, 1.5% in 2026-2027 and 1.9% in 2028-2030. Directive (EU) 2023/1791 | E8: TA7.9 | F8: TA7 - Towards a zero-pollution ambition for a toxic free environment | G8: Improve Air Quality | H8: Improve air quality to reduce the number of premature deaths caused by air pollution by 55% by 2030 | I8: + | J8: #1FA139 | K8: 2 | L8: The implementation of TA2.41 will lead to a reduction in energy consumption, which in turn will reduce the amount of pollutants released into the air, thus improving air quality and reducing premature deaths caused by air pollution, as stated in TA7.9. | M8: ok | N8: Castellazzi Luca | O8: 8
A9: TA2.22 | B9: TA2 - Clean, affordable and secure energy | C9: Energy Efficiency | D9: Member States shall collectively ensure a reduction of energy consumption of at least 11.7% in 2030 compared to the projections of the 2020 EU Reference Scenario | E9: TA7.13 | F9: TA7 - Towards a zero-pollution ambition for a toxic free environment | G9: Improve Air Quality | H9: Reduce by 25% the EU ecosystems where air pollution threatens biodiversity, by 2030 | I9: + | J9: #1FA139 | K9: 2 | L9: The reduction in energy consumption, as stated in TA2.22, will lead to a decrease in air pollution, which in turn will reduce the number of EU ecosystems where air pollution threatens biodiversity, thus supporting the objective of TA7.13. | N9: Castellazzi Luca | O9: 8
A10: TA2.41 | B10: TA2 - Clean, affordable and secure energy | C10: Energy Efficiency | D10: Member States are required to achieve cumulative end-use energy savings from 2021 to 2030, equivalent to new annual savings of at least 0.8% of final energy consumption in 2021-2023, at least 1.3% in 2024-2025, 1.5% in 2026-2027 and 1.9% in 2028-2030. Directive (EU) 2023/1791 | E10: TA7.15 | F10: TA7 - Towards a zero-pollution ambition for a toxic free environment | G10: Improve Soils Health | H10: Having all soils in healthy condition by 2050 | I10: + | J10: #1FA139 | K10: 1 | L10: The implementation of TA2.41 will lead to a reduction in energy consumption, which in turn will reduce the amount of pollutants released into the soil, thus improving soil quality and contributing to the objective of having all soils in healthy condition by 2050, as stated in TA7.15. | N10: Castellazzi Luca | O10: 8
A11: TA2.41 | B11: TA2 - Clean, affordable and secure energy | C11: Energy Efficiency | D11: Member States are required to achieve cumulative end-use energy savings from 2021 to 2030, equivalent to new annual savings of at least 0.8% of final energy consumption in 2021-2023, at least 1.3% in 2024-2025, 1.5% in 2026-2027 and 1.9% in 2028-2030. Directive (EU) 2023/1791 | E11: TA7.9 | F11: TA7 - Towards a zero-pollution ambition for a toxic free environment | G11: Improve Air Quality | H11: Improve air quality to reduce the number of premature deaths caused by air pollution by 55% by 2030 | I11: + | J11: #1FA139 | K11: 2 | L11: The reduction of energy consumption will help to minimize the environmental impacts of energy production, making it more feasible to achieve the air quality targets. | M11: duplication? | N11: Castellazzi Luca | O11: 8
A12: TA2.22 | B12: TA2 - Clean, affordable and secure energy | C12: Energy Efficiency | D12: Member States shall collectively ensure a reduction of energy consumption of at least 11.7% in 2030 compared to the projections of the 2020 EU Reference Scenario | E12: TA7.13 | F12: TA7 - Towards a zero-pollution ambition for a toxic free environment | G12: Improve Air Quality | H12: Reduce by 25% the EU ecosystems where air pollution threatens biodiversity, by 2030 | I12: + | J12: #1FA139 | K12: 2 | L12: The reduction of energy consumption will help to minimize the environmental impacts of energy production, making it more feasible to achieve the biodiversity targets. | M12: duplication? | N12: Castellazzi Luca | O12: 8
A13: TA4.34 | B13: TA4 - Sustainable and smart mobility | C13: Energy Efficiency | D13: Member States shall ensure that a minimum shore-side electricity supply for seagoing container ships and seagoing passenger ships is provided in TEN-T maritime ports. To that end, by 31 December 2029 TEN-T core and comprehensive maritime ports [...] are equipped to provide each year shore-side electricity supply for at least 90 % of the total number of port calls of seagoing container ships above 5.000 gross tonnes that are moored at the quayside at the maritime port concerned and 90% of the total number of port calls of seagoing ro-ro passenger ships above 5.000 gross tonnes and seagoing high-speed passenger craft above 5.000 gross tonnes that are moored at the quayside at the maritime port concerned Regulation (EU) 2023/1804 | E13: TA6.34 | F13: TA6 - Preserving and protecting biodiversity | G13: Biodiversity Protection & Conservation - Monitoring | H13: Terrestrial, coastal and freshwater ecosystems. Member States shall ensure that condition is known for at least 90% of the area distributed overall habitat types listed in Annex I by 2030 and 100% by 2040. | I13: + | J13: #1FA139 | K13: 1 | L13: The provision of shore-side electricity supply could support the protection of marine ecosystems and habitats, potentially contributing to the knowledge of the condition of terrestrial, coastal, and freshwater ecosystems. | N13: Castellazzi Luca | O13: 8
A14: TA4.10 | B14: TA4 - Sustainable and smart mobility | C14: Energy Efficiency | D14: EU fisheries are encouraged to continue the positive trend, as observed for the period 2009-2019, towards reducing fuel intensity by reducing the fossil-fuel consumption per kg of landed product for at least an additional 15% for the period 2019-2030. Energy Transition of the EU Fisheries and Aquaculture sector | E14: TA5.30 | F14: TA5 - Greening the Common Agricultural Policy - Farm to Fork Strategy | G14: Food affordability | H14: Food affordability: Ensure affordability to sufficient, nutritious and sustainable food | I14: + | J14: #1FA139 | K14: 2 | L14: The reduction of fuel intensity in the fisheries sector can support the development of sustainable and resilient food systems by promoting the use of renewable energy sources and reducing greenhouse gas emissions, which can contribute to ensuring food affordability. | N14: Castellazzi Luca | O14: 8
A15: TA1.8 | B15: TA1 - Climate ambition | C15: Energy Efficiency | D15: Reach energy neutrality in the wastewater treatment sector by 2045. | E15: TA7.9 | F15: TA7 - Towards a zero-pollution ambition for a toxic free environment | G15: Improve Air Quality | H15: Improve air quality to reduce the number of premature deaths caused by air pollution by 55% by 2030 | I15: + | J15: #1FA139 | K15: 2 | L15: Reaching energy neutrality in the wastewater treatment sector will enable the improvement of air quality, as it will lead to a decrease in energy consumption and emissions, thus reducing air pollution. | N15: Castellazzi Luca | O15: 8
A16: TA1.8 | B16: TA1 - Climate ambition | C16: Energy Efficiency | D16: Reach energy neutrality in the wastewater treatment sector by 2045 | E16: TA7.5 | F16: TA7 - Towards a zero-pollution ambition for a toxic free environment | G16: Improve Water Quality | H16: The revised Urban Wastewater Treatment Directive (UWWTD) extends the scope of the 1991 UWWTD | I16: + | J16: #1FA139 | K16: 1 | L16: The revised UWWTD will contribute to reaching energy neutrality in the wastewater treatment sector by 2045. | N16: Castellazzi Luca | O16: 8
A17: TA2.41 | B17: TA2 - Clean, affordable and secure energy | C17: Energy Efficiency | D17: Member States are required to achieve cumulative end-use energy savings from 2021 to 2030, equivalent to new annual savings of at least 0.8% of final energy consumption in 2021-2023, at least 1.3% in 2024-2025, 1.5% in 2026-2027 and 1.9% in 2028-2030 | E17: TA3.31 | F17: TA3 - Industrial strategy for a clean and circular economy | G17: Circularity/Recycling - Municipal Waste | H17: Member States shall take the necessary measures to attain the recycling targets of 65% by weight of all packaging waste generated by 31 December 2025, and of 70% by weight of all packaging waste generated by 31 December 2030. Proposal on packaging and packaging waste | I17: + | J17: #1FA139 | K17: 2 | L17: The implementation of TA2.41 may enable TA3.31, which aims to increase recycling targets for packaging waste, as increased energy efficiency and reduced energy consumption may lead to reduced packaging waste generation, thus supporting the transition to a more circular economy. | N17: Castellazzi Luca | O17: 8
A18: TA2.22 | B18: TA2 - Clean, affordable and secure energy | C18: Energy Efficiency | D18: Member States shall collectively ensure a reduction of energy consumption of at least 11.7% in 2030 compared to the projections of the 2020 EU Reference Scenario | E18: TA4.18 | F18: TA4 - Sustainable and smart mobility | G18: Biofuels | H18: The share of biofuels and biogas produced from the feedstock listed in Part B of Annex IX in the energy content of fuels and electricity supplied to the transport sector shall, except in Cyprus and Malta, be limited to 1.7%. Directive (EU) 2023/2413 | I18: - | J18: #DA2620 | K18: 1 | L18: The implementation of TA2.22, which aims to reduce energy consumption, may have a negative impact on TA4.18, which limits the share of biofuels and biogas produced from certain feedstocks. By reducing energy consumption, TA2.22 may lead to decreased production of biofuels and biogas, thus hindering the achievement of TA4.18. | N18: Castellazzi Luca | O18: 8
A19: TA2.21 | B19: TA2 - Clean, affordable and secure energy | C19: Energy Efficiency | D19: Member States shall ensure that the total final energy consumption of all public bodies combined is reduced by at least 1.9% each year, when compared to 2021 | E19: TA1.3 | F19: TA1 - Climate ambition | G19: GHG Reduction | H19: Reduce by at least 55% net GHG emissions compared to 1990 levels, by 2030 | I19: + | J19: #1FA139 | K19: 3 | L19: The implementation of TA2.21 may enable the achievement of TA1.3, as reducing energy consumption in public bodies may not be sufficient to achieve the GHG emissions reduction target. | N19: Castellazzi Luca | O19: 8
A20: TA2.23 | B20: TA2 - Clean, affordable and secure energy | C20: Energy Efficiency | D20: Member States shall make efforts to collectively contribute to the indicative Union primary energy consumption target amounting to no more than 992.5 Mtoe in 2030 | E20: TA1.3 | F20: TA1 - Climate ambition | G20: GHG Reduction | H20: Reduce by at least 55% net GHG emissions compared to 1990 levels, by 2030 | I20: + | J20: #1FA139 | K20: 3 | L20: The implementation of TA2.23 may enable the achievement of TA1.3, as reducing primary energy consumption may not be sufficient to achieve the GHG emissions reduction target. | N20: Castellazzi Luca | O20: 8
A21: TA2.41 | B21: TA2 - Clean, affordable and secure energy | C21: Energy Efficiency | D21: Member States are required to achieve cumulative end-use energy savings from 2021 to 2030, equivalent to new annual savings of at least 0.8% of final energy consumption in 2021-2023, at least 1.3% in 2024-2025, 1.5% in 2026-2027 and 1.9% in 2028-2030 | E21: TA4.1 | F21: TA4 - Sustainable and smart mobility | G21: Biofuels | H21: Achieve an annual production of sustainable biomethane of 35 billion cubic meters by 2030 | I21: + | J21: #1FA139 | K21: 1 | L21: The implementation of TA2.41, which aims to achieve cumulative end-use energy savings, may have a positive impact on TA4.1, which targets the production of sustainable biomethane. By reducing energy consumption, TA2.41 can lead to increased availability of biomass for biomethane production, thus supporting the achievement of TA4.1. | N21: Castellazzi Luca | O21: 8
A22: TA2.21 | B22: TA2 - Clean, affordable and secure energy | C22: Energy Efficiency | D22: Member States shall ensure that the total final energy consumption of all public bodies combined is reduced by at least 1.9% each year, when compared to 2021 | E22: TA5.11 | F22: TA5 - Greening the Common Agricultural Policy - Farm to Fork Strategy | G22: Biodiversity Protection & Conservation | H22: Biodiversity conservation and restoration of natural resources: Protect the environment and restore natural resources. Preserve biodiversity and reduce biodiversity loss. | I22: + | J22: #1FA139 | K22: 1 | L22: The reduction of energy consumption in public bodies, as per TA2.21, can contribute to the conservation and restoration of natural resources, as outlined in TA5.11, by minimizing the environmental footprint of public institutions (and promoting sustainable food systems?) | M22: mah…. | N22: Castellazzi Luca | O22: 8
A23: TA2.21 | B23: TA2 - Clean, affordable and secure energy | C23: Energy Efficiency | D23: Member States shall ensure that the total final energy consumption of all public bodies combined is reduced by at least 1.9% each year, when compared to 2021 | E23: TA7.4 | F23: TA7 - Towards a zero-pollution ambition for a toxic free environment | G23: Improve Air Quality | H23: The Industrial Emissions Directive (IED) aims at preventing or reducing emissions from large industrial installations and intensive farming into the environment. | I23: + | J23: #1FA139 | K23: 1 | L23: The reduction of energy consumption will help to minimize the environmental impacts of public activities, making it more feasible to achieve the emissions reduction targets. | N23: Castellazzi Luca | O23: 8
A24: TA4.33 | B24: TA4 - Sustainable and smart mobility | C24: Energy Efficiency | D24: Member States shall ensure that at least one installation providing shore-side electricity supply to inland waterway vessels is deployed at all TEN-T core inland waterway ports by 1 January 2025, at least one installation providing shore-side electricity supply to inland waterway vessels is deployed at all TEN-T comprehensive inland waterway ports by 1 January 2030. Regulation (EU) 2023/1804 | E24: TA2.22 | F24: TA2 - Clean, affordable and secure energy | G24: Energy Efficiency | H24: Member States shall collectively ensure a reduction of energy consumption of at least 11.7% in 2030 compared to the projections of the 2020 EU Reference Scenario | I24: + | J24: #1FA139 | K24: 1 | L24: The implementation of TA4.33 could enable the achievement of TA2.22 by reducing energy consumption in the inland waterway sector, thus allowing for a greater share of renewable energy in the energy mix. | M24: to be replaced with: The implementation of TA4.33 could enable the achievement of TA2.22 by reducing energy consumption in the inland waterway sector. | N24: Castellazzi Luca | O24: 8
A25: TA4.10 | B25: TA4 - Sustainable and smart mobility | C25: Energy Efficiency | D25: EU fisheries are encouraged to continue the positive trend, as observed for the period 2009-2019, towards reducing fuel intensity by reducing the fossil-fuel consumption per kg of landed product for at least an additional 15% for the period 2019-2030. Energy Transition of the EU Fisheries and Aquaculture sector | E25: TA2.23 | F25: TA2 - Clean, affordable and secure energy | G25: Energy Efficiency | H25: Member States shall make efforts to collectively contribute to the indicative Union primary energy consumption target amounting to no more than 992.5 Mtoe in 2030 | I25: + | J25: #1FA139 | K25: 1 | L25: The implementation of TA4.10 could support the achievement of TA2.23 by reducing energy consumption in the fisheries sector, thus allowing for a greater share of renewable energy in the energy mix. | N25: Castellazzi Luca | O25: 8
A26: TA4.34 | B26: TA4 - Sustainable and smart mobility | C26: Energy Efficiency | D26: Member States shall ensure that a minimum shore-side electricity supply for seagoing container ships and seagoing passenger ships is provided in TEN-T maritime ports. To that end, by 31 December 2029 TEN-T core and comprehensive maritime ports [...] are equipped to provide each year shore-side electricity supply for at least 90 % of the total number of port calls of seagoing container ships above 5.000 gross tonnes that are moored at the quayside at the maritime port concerned and 90% of the total number of port calls of seagoing ro-ro passenger ships above 5.000 gross tonnes and seagoing high-speed passenger craft above 5.000 gross tonnes that are moored at the quayside at the maritime port concerned Regulation (EU) 2023/1804 | E26: TA7.14 | F26: TA7 - Towards a zero-pollution ambition for a toxic free environment | G26: Noise Reduction | H26: Reduce the share of people chronically disturbed by transport noise by 30%, by 2030 | I26: + | J26: #1FA139 | K26: 1 | L26: The provision of shore-side electricity supply for seagoing container ships and passenger ships can help reduce noise pollution from transport operations, thus reducing the number of people chronically disturbed by transport noise. | N26: Castellazzi Luca | O26: 8
A27: TA4.10 | B27: TA4 - Sustainable and smart mobility | C27: Energy Efficiency | D27: EU fisheries are encouraged to continue the positive trend, as observed for the period 2009-2019, towards reducing fuel intensity by reducing the fossil-fuel consumption per kg of landed product for at least an additional 15% for the period 2019-2030. Energy Transition of the EU Fisheries and Aquaculture sector | E27: TA7.5 | F27: TA7 - Towards a zero-pollution ambition for a toxic free environment | G27: Improve Water Quality | H27: The revised Urban Wastewater Treatment Directive (UWWTD) extends the scope of the 1991 UWWTD | I27: + | J27: #1FA139 | K27: 2 | L27: The reduction of fuel intensity in the EU fisheries sector can lead to a decrease in wastewater and pollution from fishing activities, thus contributing to improved water quality and reduced pollution. | N27: Castellazzi Luca | O27: 8
A28: TA4.33 | B28: TA4 - Sustainable and smart mobility | C28: Energy Efficiency | D28: Member States shall ensure that at least one installation providing shore-side electricity supply to inland waterway vessels is deployed at all TEN-T core inland waterway ports by 1 January 2025, at least one installation providing shore-side electricity supply to inland waterway vessels is deployed at all TEN-T comprehensive inland waterway ports by 1 January 2030. Regulation (EU) 2023/1804 | E28: TA6.28 | F28: TA6 - Preserving and protecting biodiversity | G28: Biodiversity Protection & Conservation - Fisheries | H28: In accordance with the CFP, it is crucial to continue and accelerate the work of rebuilding and keeping fish stocks above MSY levels | I28: + | J28: #1FA139 | K28: 1 | L28: The deployment of shore-side electricity supply installations could support the protection of aquatic ecosystems and the rebuilding of fish stocks. | N28: Castellazzi Luca | O28: 8
A29: TA4.34 | B29: TA4 - Sustainable and smart mobility | C29: Energy Efficiency | D29: Member States shall ensure that a minimum shore-side electricity supply for seagoing container ships and seagoing passenger ships is provided in TEN-T maritime ports. To that end, by 31 December 2029 TEN-T core and comprehensive maritime ports [...] are equipped to provide each year shore-side electricity supply for at least 90 % of the total number of port calls of seagoing container ships above 5.000 gross tonnes that are moored at the quayside at the maritime port concerned and 90% of the total number of port calls of seagoing ro-ro passenger ships above 5.000 gross tonnes and seagoing high-speed passenger craft above 5.000 gross tonnes that are moored at the quayside at the maritime port concerned Regulation (EU) 2023/1804 | E29: TA5.25 | F29: TA5 - Greening the Common Agricultural Policy - Farm to Fork Strategy | G29: Food quality - Animal Welfare | H29: Animal welfare: Promote better animal welfare to improve animal health and food quality. | I29: + | J29: #1FA139 | K29: 1 | L29: The provision of shore-side electricity supply to seagoing vessels can support the promotion of animal welfare by reducing the environmental impact of maritime transport and promoting sustainable and resilient food systems. | M29: yes, for fishes | N29: Castellazzi Luca | O29: 8
A30: TA4.10 | B30: TA4 - Sustainable and smart mobility | C30: Energy Efficiency | D30: EU fisheries are encouraged to continue the positive trend, as observed for the period 2009-2019, towards reducing fuel intensity by reducing the fossil-fuel consumption per kg of landed product for at least an additional 15% for the period 2019-2030. Energy Transition of the EU Fisheries and Aquaculture sector | E30: TA7.5 | F30: TA7 - Towards a zero-pollution ambition for a toxic free environment | G30: Improve Water Quality | H30: The revised Urban Wastewater Treatment Directive (UWWTD) extends the scope of the 1991 UWWTD | I30: + | J30: #1FA139 | K30: 1 | L30: The revised UWWTD can support the energy transition in the fisheries and aquaculture sector by reducing emissions from wastewater treatment, thus creating a more favorable environment for the reduction of fuel intensity. | N30: Castellazzi Luca | O30: 8
A31: TA4.20 | B31: TA4 - Sustainable and smart mobility | C31: Renewable Energy - Hydrogen Production | D31: In the first phase, from 2020 up to 2024, the strategic objective is to install at least 6 GW of renewable hydrogen electrolysers in the EU. In the second phase, from 2025 up to 2030, the strategic objective is to install at least 40 GW of renewable hydrogen electrolysers. A Hydrogen Strategy for a climate-neutral Europe | E31: TA2.41 | F31: TA2 - Clean, affordable and secure energy | G31: Energy Efficiency | H31: Member States are required to achieve cumulative end-use energy savings from 2021 to 2030, equivalent to new annual savings of at least 0.8% of final energy consumption in 2021-2023, at least 1.3% in 2024-2025, 1.5% in 2026-2027 and 1.9% in 2028-2030. Directive (EU) 2023/1791 | I31: + | J31: #1FA139 | K31: 1 | L31: The implementation of TA4.20 could reinforce the achievement of TA2.41 by increasing the share of renewable energy in the energy mix, thus contributing to the reduction of energy consumption and the increase of the share of renewable energy. | M31: this is true only if the produced GREEN H2 is used in a way that the final enrgy consumption are reduced (e.g. in a fuel cell in a car) the LLM is often confusing RES and EE reletionship | N31: Castellazzi Luca | O31: 8
A32: TA4.33 | B32: TA4 - Sustainable and smart mobility | C32: Energy Efficiency | D32: Member States shall ensure that at least one installation providing shore-side electricity supply to inland waterway vessels is deployed at all TEN-T core inland waterway ports by 1 January 2025, at least one installation providing shore-side electricity supply to inland waterway vessels is deployed at all TEN-T comprehensive inland waterway ports by 1 January 2030. Regulation (EU) 2023/1804 | E32: TA2.22 | F32: TA2 - Clean, affordable and secure energy | G32: Energy Efficiency | H32: Member States shall collectively ensure a reduction of energy consumption of at least 11.7% in 2030 compared to the projections of the 2020 EU Reference Scenario | I32: + | J32: #1FA139 | K32: 2 | L32: The implementation of TA4.33 could enable the achievement of TA2.22 by reducing energy consumption in the inland waterway sector, thus allowing for a greater share of renewable energy in the energy mix. | N32: Castellazzi Luca | O32: 8
A33: TA4.10 | B33: TA4 - Sustainable and smart mobility | C33: Energy Efficiency | D33: EU fisheries are encouraged to continue the positive trend, as observed for the period 2009-2019, towards reducing fuel intensity by reducing the fossil-fuel consumption per kg of landed product for at least an additional 15% for the period 2019-2030. Energy Transition of the EU Fisheries and Aquaculture sector | E33: TA2.23 | F33: TA2 - Clean, affordable and secure energy | G33: Energy Efficiency | H33: Member States shall make efforts to collectively contribute to the indicative Union primary energy consumption target amounting to no more than 992.5 Mtoe in 2030 | I33: + | J33: #1FA139 | K33: 2 | L33: The implementation of TA4.10 could support the achievement of TA2.23 by reducing energy consumption in the fisheries sector, thus allowing for a greater share of renewable energy in the energy mix. | N33: Castellazzi Luca | O33: 8
A34: TA2.17 | B34: TA2 - Clean, affordable and secure energy | C34: Energy Infrastructure | D34: A target of 15% electricity interconnection for 2030 | E34: TA4.33 | F34: TA4 - Sustainable and smart mobility | G34: Energy Efficiency | H34: Member States shall ensure that at least one installation providing shore-side electricity supply to inland waterway vessels is deployed at all TEN-T core inland waterway ports by 1 January 2025, at least one installation providing shore-side electricity supply to inland waterway vessels is deployed at all TEN-T comprehensive inland waterway ports by 1 January 2030. Regulation (EU) 2023/1804 | I34: + | J34: #1FA139 | K34: 1 | L34: The implementation of TA2.17, which aims to achieve a target of 15% electricity interconnection, may have a positive impact on TA4.33, which targets the deployment of shore-side electricity supply to inland waterway vessels. By increasing electricity interconnection, TA2.17 can support the achievement of TA4.33. | N34: Castellazzi Luca | O34: 8
A35: TA3.24 | B35: TA3 - Industrial strategy for a clean and circular economy | C35: Waste Reduction - Food Waste | D35: Reduce the generation of food waste in processing and manufacturing by 10% in comparison to the amount generated in 2020 | E35: TA2.41 | F35: TA2 - Clean, affordable and secure energy | G35: Energy Efficiency | H35: Member States are required to achieve cumulative end-use energy savings from 2021 to 2030, equivalent to new annual savings of at least 0.8% of final energy consumption in 2021-2023, at least 1.3% in 2024-2025, 1.5% in 2026-2027 and 1.9% in 2028-2030 Directive (EU) 2023/1791 | I35: + | J35: #1FA139 | K35: 2 | L35: The implementation of TA3.24 could support TA2.41 by reducing food waste, which could lead to increased energy savings. | N35: Castellazzi Luca | O35: 8
A36: TA3.3 | B36: TA3 - Industrial strategy for a clean and circular economy | C36: Circularity/Recycling | D36: Double EU‚Äö√Ñ√¥s circular material use rate in the coming decade | E36: TA2.41 | F36: TA2 - Clean, affordable and secure energy | G36: Energy Efficiency | H36: Member States are required to achieve cumulative end-use energy savings from 2021 to 2030, equivalent to new annual savings of at least 0.8% of final energy consumption in 2021-2023, at least 1.3% in 2024-2025, 1.5% in 2026-2027 and 1.9% in 2028-2030. Directive (EU) 2023/1791 | I36: + | J36: #1FA139 | K36: 2 | L36: The implementation of TA3.3 could reinforce TA2.41 by promoting energy efficiency and reducing energy consumption, which in turn could lead to increased energy savings and a higher share of renewable energy in the energy mix. | N36: Castellazzi Luca | O36: 8
A37: TA3.52 | B37: TA3 - Industrial strategy for a clean and circular economy | C37: Circularity/Recycling - Plastic & Packaging | D37: At least 20% of the carbon used in the chemical and plastic products should be from sustainable non-fossil sources by 2030, in full consideration of the EU's biodiversity and circular economy objectives and of the upcoming policy framework for bio-based, biodegradable and compostable plastics Communication on Sustainable Carbon Cycles | E37: TA2.41 | F37: TA2 - Clean, affordable and secure energy | G37: Energy Efficiency | H37: Member States are required to achieve cumulative end-use energy savings from 2021 to 2030, equivalent to new annual savings of at least 0.8% of final energy consumption in 2021-2023, at least 1.3% in 2024-2025, 1.5% in 2026-2027 and 1.9% in 2028-2030 Directive (EU) 2023/1791 | I37: + | J37: #1FA139 | K37: 1 | L37: The implementation of TA3.52 could support TA2.41 by promoting the use of sustainable non-fossil carbon sources, which could lead to increased energy savings. | N37: Castellazzi Luca | O37: 8
A38: TA4.1 | B38: TA4 - Sustainable and smart mobility | C38: Biofuels | D38: Achieve an annual production of sustainable biomethane of 35 billion cubic meters by 2030 | E38: TA2.41 | F38: TA2 - Clean, affordable and secure energy | G38: Energy Efficiency | H38: Member States are required to achieve cumulative end-use energy savings from 2021 to 2030, equivalent to new annual savings of at least 0.8% of final energy consumption in 2021-2023, at least 1.3% in 2024-2025, 1.5% in 2026-2027 and 1.9% in 2028-2030. Directive (EU) 2023/1791 | I38: + | J38: #1FA139 | K38: 1 | L38: The implementation of TA4.1 could reinforce the achievement of TA2.41 by increasing the share of renewable energy in the energy mix, thus contributing to the reduction of energy consumption. | M38: this is true only if the production of the biomethane consumes less than the production of the substituted fuel | N38: Castellazzi Luca | O38: 8
A39: TA5.27 | B39: TA5 - Greening the Common Agricultural Policy - Farm to Fork Strategy | C39: Food quality - Healthy Food | D39: Food messaging: Provide food information and labelling to empower consumers to make informed, healthy and sustainable food choices. Strengthen educational messages on the importance of healthy nutrition, sustainable food production and consumption, and reducing food waste | E39: TA4.10 | F39: TA4 - Sustainable and smart mobility | G39: Energy Efficiency | H39: EU fisheries are encouraged to continue the positive trend, as observed for the period 2009-2019, towards reducing fuel intensity by reducing the fossil-fuel consumption per kg of landed product for at least an additional 15% for the period 2019-2030. Energy Transition of the EU Fisheries and Aquaculture sector | I39: + | J39: #1FA139 | K39: 2 | L39: The implementation of TA5.27 could support the achievement of TA4.10 by promoting sustainable food systems and reducing food waste, increasing the use of renewable energy in fisheries and aquaculture. | N39: Castellazzi Luca | O39: 8
A40: TA6.33 | B40: TA6 - Preserving and protecting biodiversity | C40: Biodiversity Protection & Conservation | D40: Terrestrial, coastal and freshwater ecosystems. Member States shall put in place the restoration measures for the terrestrial, coastal and freshwater habitats of the species listed in Annexes II, IV and V | E40: TA2.23 | F40: TA2 - Clean, affordable and secure energy | G40: Energy Efficiency | H40: Member States shall make efforts to collectively contribute to the indicative Union primary energy consumption target amounting to no more than 992.5 Mtoe in 2030 | I40: + | J40: #1FA139 | K40: 2 | L40: The restoration of ecosystems can lead to the reduction of energy consumption, as restored ecosystems can provide ecosystem services, such as carbon sequestration, which can reduce the need for energy-intensive practices. | N40: Castellazzi Luca | O40: 8
...

Sheet all_targets
A1: thematic - area | B1: sub_theme | C1: sub_theme_color | D1: target_code | E1: is_source_target | F1: is_impact_target | G1: target_content | H1: target_assessment | I1: policy_document
A2: TA1 - Climate ambition | B2: GHG Reduction - Buildings | C2: #DDEBF7 | D2: TA1.10 | E2: =ISNUMBER(MATCH(D2,data!A:A)) -> TRUE | F2: =ISNUMBER(MATCH(D2,data!E:E)) -> TRUE | G2: ETS2. Contribution of the buildings and road transport sectors of 43% emission reductions by 2030 compared to 2005 | H2: The ETS2 is a new EU-wide cap-and-trade economic instrument that covers the CO2 emissions from the combustion of fuels in road transport, buildings, and other sectors (mainly smaller industries), excluding agriculture. Monitoring starts in 2025, with cap and trade applying from 2027. As such, it overlaps significantly with the ESR in terms of sectors covered, but important differences are that a) it is implemented at the EU level, rather than through Member State-specific policies, and b) it does not cover non-CO2 emissions, many of which are from the hard-to- tackle agricultural sector. Between 2005 and 2022, the emissions covered by the ETS 2 fell by 16% according to own estimates of the JRC. However, since the ETS2 instrument is newly implemented and official reporting by Member States is not yet available, the progress cannot currently be evaluated. | I2: Amending Directive 2003/87/EC establishing a system for greenhouse gas emission allowance trading within the Union, Decision (EU) 2015/1814 concerning the establishment and operation of a market stability reserve for the Union greenhouse gas emission trading system
B3: GHG Reduction - Transports | C3: #DDEBF7 | D3: TA1.10 | E3: =ISNUMBER(MATCH(D3,data!A:A)) -> TRUE | F3: =ISNUMBER(MATCH(D3,data!E:E)) -> TRUE | G3: ETS2. Contribution of the buildings and road transport sectors of 43% emission reductions by 2030 compared to 2005 | H3: The ETS2 is a new EU-wide cap-and-trade economic instrument that covers the CO2 emissions from the combustion of fuels in road transport, buildings, and other sectors (mainly smaller industries), excluding agriculture. Monitoring starts in 2025, with cap and trade applying from 2027. As such, it overlaps significantly with the ESR in terms of sectors covered, but important differences are that a) it is implemented at the EU level, rather than through Member State-specific policies, and b) it does not cover non-CO2 emissions, many of which are from the hard-to- tackle agricultural sector. Between 2005 and 2022, the emissions covered by the ETS 2 fell by 16% according to own estimates of the JRC. However, since the ETS2 instrument is newly implemented and official reporting by Member States is not yet available, the progress cannot currently be evaluated. | I3: Amending Directive 2003/87/EC establishing a system for greenhouse gas emission allowance trading within the Union, Decision (EU) 2015/1814 concerning the establishment and operation of a market stability reserve for the Union greenhouse gas emission trading system
B4: GHG Reduction | C4: #DDEBF7 | D4: TA1.11 | E4: =ISNUMBER(MATCH(D4,data!A:A)) -> TRUE | F4: =ISNUMBER(MATCH(D4,data!E:E)) -> TRUE | G4: ESR. Increased national targets in line with an EU- wide reduction of 40% in the ESR sectors compared to 2005 | H4: The current (2022) reduction is 17% relative to 2005, far from the 40% reduction target set for 2030. Between 2013 and 2020, Member States met or overa- chieved their ESR obligations- with the largest reductions in the buildings and small industry sectors. Emissions are expected to continue decreasing in the com- ing decade due to –among others- source control legislation, such as improved building standards, building renovations, CO2 standards for road vehicles and EU policies on phasing down hydrofluorocarbons (HFC) and other fluorinated gases. Progress in the transport and building sectors faces different challenges. While transport emissions are regulated by EU-wide CO2 emission standards for vehicles (which have a relatively fast turnover rate), renovating the building stock is a more challenging effort, primarily driven by Member States' policies. Therefore, Member States' projections for building emissions significantly lag behind the expected cost-effective rate of reduction [31]. Overall, EU emissions in the sectors covered by the ESR, according to 2023 Member States projections, are expected to fall by 27-32% (with existing and ad- ditional measures, respectively) by 2030 compared to 2005, i.e. 8 -13 percentage points below the 40% target for 2030, with only 6 Member States projected to (over-) achieve their targets [22]. Absolute emissions in the agriculture sector have stagnated since 2010, while agricultural aggregate output has increased, decreasing emission intensity of EU agricultural products by 13%. Concerning emission reductions, current Member States' projections under the Governance Regulation foresee 2030 emissions with existing measures to be 373 MtCO2e (or -3% compared to 2021) and 359 MtCO2e (or -7 %) with additional measures. The 2030 ‘MIX (55 Euro/t CO2e)’ scenario, used to assess the Fit for 55 targets corresponds to a -7 % decline in the agricultural sector by 2030 compared to 2021, aligning with the Member States ‘with additional measures’ scenario. The current (2023-2027) CAP aims to contribute to climate mitigation, with Member State strategies outlined in their Strategic Plans. Estimates of the CAP 2023-2027 impact on emissions require detailed information on the implementation and effectiveness of farming practices from the CAP instruments, which are currently being evaluated. | I4: Amending Regulation (EU) 2018/842 on binding annual greenhouse gas emission reductions by Member States from 2021 to 2030 contributing to climate action to meet commitments under the Paris Agreement, and Regulation (EU) 2018/1999
B5: GHG Removal | C5: #DDEBF7 | D5: TA1.12 | E5: =ISNUMBER(MATCH(D5,data!A:A)) -> TRUE | F5: =ISNUMBER(MATCH(D5,data!E:E)) -> TRUE | G5: Achieve an EU net greenhouse gas removal of 310 million tonnes CO2 equivalent per year for the land use, land use change and forestry (LULUCF) sector, by 2030 | H5: The revised LULUCF regulation sets a target of removing 310 MtCO2e by 2030. The long-term EU forest sink is developing away from this target and jeopard- ising the fulfilment of the overall LULUCF sector target for 2030. Furthermore, natural disturbances are expected to increase with ongoing climate change, with potentially a further reduction of the carbon sink, making the situation even more difficult. In 2020, the gap between the reported LULUCF emissions in 2016-2018 and the target of -310 MtCO2e for 2030 was -42 MtCO2e for the EU. 2024 shows that this gap has now widened: instead of -42 MtCO2e, the EU needs to improve its LULUCF sink by -80 MtCO2e between 2022 and 2030 to meet the targets. The LULUCF targets will be difficult to achieve unless substantial changes in forest manage- ment are implemented very soon. | I5: Amending Regulations (EU) 2018/841 as regards the scope, simplifying the compliance rules, setting out the targets of the Member States for 2030 and committing to the collective achievement of climate neutrality by 2035 in the land use, forestry and agriculture sector, and (EU) 2018/1999 as regards improvement in monitoring, reporting, tracking of progress and review
B6: GHG Reduction | C6: #DDEBF7 | D6: TA1.13 | E6: =ISNUMBER(MATCH(D6,data!A:A)) -> TRUE | F6: =ISNUMBER(MATCH(D6,data!E:E)) -> TRUE | G6: No debit rule. For the period from 2021 to 2025, each Member State shall ensure that greenhouse gas emissions from the sector do not exceed greenhouse gas removals | H6: Assessing the distance to the target is difficult. Comparing purely the GHG re- porting from countries for 2021 and 2022, to the accounting benchmark of -229 MtCO2e determined by the delegated act, it looks like the EU is slightly exceeding the accounting benchmark. However, the recalculations of the inventories have increased the net sink historical time series reported by the Member States, and those recalculations will be considered in the accounting. Given the sharp decline of the forest sink driven by increasing harvest levels and natural disturbances, it is likely that the EU will face an overall accounting debit (i.e. not reaching the target) than a credit in the LULUCF sector as a whole. The reporting for years 2026-2029 will be done in GHG inventories during 2028- 2031. | I6: Amending Regulations (EU) 2018/841 as regards the scope, simplifying the compliance rules, setting out the targets of the Member States for 2030 and committing to the collective achievement of climate neutrality by 2035 in the land use, forestry and agriculture sector, and (EU) 2018/1999 as regards improvement in monitoring, reporting, tracking of progress and review
B7: GHG Reduction - Buildings | C7: #DDEBF7 | D7: TA1.15 | E7: =ISNUMBER(MATCH(D7,data!A:A)) -> TRUE | F7: =ISNUMBER(MATCH(D7,data!E:E)) -> TRUE | G7: Reduce buildings‚Äô greenhouse gas emissions by 60%, by 2030 | H7: In 2015 buildings direct GHG emissions were 541 MtCO2e, therefore the target value for 2030 is 216 MtCO2e. European Climate Neutrality Observatory data shows past progress of 5 MtCO2e between 2016 and 2021. To meet the target, the required annual change between 2021 and 2030 needs to be 7.5 times faster than the past rate of progress. Overall, buildings are responsible for about 40% of the EU’s total energy consumption, and for 36% of its greenhouse gas emissions from energy (including indirect emissions). Buildings related emissions belonging to fossil fuelled district heating, electric heating and electricity use of heat pumps are covered by EU ETS, while the rest is covered by the ESR. | I7: A Renovation Wave for Europe - greening our buildings, creating jobs, improving lives
B8: Climate Resilience | C8: #DDEBF7 | D8: TA1.3 | E8: =ISNUMBER(MATCH(D8,data!A:A)) -> TRUE | F8: =ISNUMBER(MATCH(D8,data!E:E)) -> TRUE | G8: Reduce by at least 55% net GHG emissions compared to 1990 levels, by 2030 | H8: The at least 55% economy-wide net reduction objective is enshrined in the Climate Law as an overall ambition at the EU level. Specific legislation covering different sectors translates this into sectoral ambition levels which cumulatively achieve the -55% target. This corresponds to greenhouse gas reductions of 62% in the existing ETS compared to 2005, a 40% reduction in ESR, (this is now complemented by 42% reduction target compared to 2005 in the newly established ETS2). With the aim of ensuring strong emissions reduction in other sectors, the overall contribution of the LULUCF sector to EU’s economy-wide target of − 55% by 2030 is limited to a maximum of − 225 MtCO2e/year. Achieving the LULUCF sector target of -310 MtCO2e in 2030 will elevate the total EU GHG emission reduction to approximately 57% compared to 1990. The total net EU greenhouse gases emissions, including LULUCF, were reduced by 32.5% between 1990 and 2022 [21]. GHG emission reductions need to double in the current decade compared to the previous decades (see charts in the annexes). According to the Member States’ own projections reported in 2023 under Article 18 of the Governance of the Energy Union Regulation, total EU emissions are expected to fall in 2030 by about 50% below the 1990 level when factoring in additional measures. This falls short of the at least 55% objective, but the Member States projections do not accurately capture the evolution driven by EU-wide instruments such as the ETS. Reaching the -55 % objective further depends on delivery of ESR, which is not fully on track, as well as the related functioning of ETS2. In addition, the -55% objective assumes that the LULUCF sink is at least -225 MtCO2e. The agreed LULUCF commitment of -310 MtCO2e could even achieve -57%. However, the current development of the LULUCF sink is opposite to the targets, including natural disturbances that are expected to further increase with the ongoing climate change [27], [28]. If this negative development continues, the risk of not reaching the sink of –225 MtCO2 cannot be ruled out. On the other hand, the implementation of the complete Fit for 55 legislative package is expected to reduce EU net greenhouse gas emissions by 57% by 2030, putting EU on track to exceed 2030 targets [29]. On the way to climate neutrality by 2050, the Commission adopted a Communica- tion [23] in February 2024 that launches the process of setting the 2040 climate target for the EU, in compliance with Art. 4.3 of the Climate Law. While 2040 targets are not yet set, it is clear that much of the transition to 2050 has to be realised by 2040. Based on the recommended emission reductions of 90-95 % by 2040 compared to 1990, of the European Scientific Advisory Board on Climate Change advised, the Commission has recommended a net 90% GHG reduction target for 2040. Both 2040 and 2050 targets require a much deeper transformation of the energy system, through large scale deployment of climate-neutral technologies that require high investment efforts with some technologies not yet deployed at market scale. While some of the current instruments will keep delivering reductions well beyond 2030 (notably the EU ETS but also CO2 standards for vehicles, ReFuelEU Aviation, FuelEU Maritime and the Fluorinated gas (F-gas) Regulation), there will be a need to review, update and complete the legislative framework for the post-2030 period. This will include topics such as carbon capture, industrial carbon removals, and overall and sector specific emission reduction trajectories. In addition, larger emis- sion reductions in difficult-to-abate sectors like agriculture will be needed, along with a larger role for carbon removals, including utilising land as a carbon sink. | I8: Establishing the framework for achieving climate neutrality and amending regulations (EC) No 401/2009 and (EU) 2018/1999 ("European Climate Law")
B9: GHG Reduction | C9: #DDEBF7 | D9: TA1.3 | E9: =ISNUMBER(MATCH(D9,data!A:A)) -> TRUE | F9: =ISNUMBER(MATCH(D9,data!E:E)) -> TRUE | G9: Reduce by at least 55% net GHG emissions compared to 1990 levels, by 2030 | H9: The at least 55% economy-wide net reduction objective is enshrined in the Climate Law as an overall ambition at the EU level. Specific legislation covering different sectors translates this into sectoral ambition levels which cumulatively achieve the -55% target. This corresponds to greenhouse gas reductions of 62% in the existing ETS compared to 2005, a 40% reduction in ESR, (this is now complemented by 42% reduction target compared to 2005 in the newly established ETS2). With the aim of ensuring strong emissions reduction in other sectors, the overall contribution of the LULUCF sector to EU’s economy-wide target of − 55% by 2030 is limited to a maximum of − 225 MtCO2e/year. Achieving the LULUCF sector target of -310 MtCO2e in 2030 will elevate the total EU GHG emission reduction to approximately 57% compared to 1990. The total net EU greenhouse gases emissions, including LULUCF, were reduced by 32.5% between 1990 and 2022 [21]. GHG emission reductions need to double in the current decade compared to the previous decades (see charts in the annexes). According to the Member States’ own projections reported in 2023 under Article 18 of the Governance of the Energy Union Regulation, total EU emissions are expected to fall in 2030 by about 50% below the 1990 level when factoring in additional measures. This falls short of the at least 55% objective, but the Member States projections do not accurately capture the evolution driven by EU-wide instruments such as the ETS. Reaching the -55 % objective further depends on delivery of ESR, which is not fully on track, as well as the related functioning of ETS2. In addition, the -55% objective assumes that the LULUCF sink is at least -225 MtCO2e. The agreed LULUCF commitment of -310 MtCO2e could even achieve -57%. However, the current development of the LULUCF sink is opposite to the targets, including natural disturbances that are expected to further increase with the ongoing climate change [27], [28]. If this negative development continues, the risk of not reaching the sink of –225 MtCO2 cannot be ruled out. On the other hand, the implementation of the complete Fit for 55 legislative package is expected to reduce EU net greenhouse gas emissions by 57% by 2030, putting EU on track to exceed 2030 targets [29]. On the way to climate neutrality by 2050, the Commission adopted a Communica- tion [23] in February 2024 that launches the process of setting the 2040 climate target for the EU, in compliance with Art. 4.3 of the Climate Law. While 2040 targets are not yet set, it is clear that much of the transition to 2050 has to be realised by 2040. Based on the recommended emission reductions of 90-95 % by 2040 compared to 1990, of the European Scientific Advisory Board on Climate Change advised, the Commission has recommended a net 90% GHG reduction target for 2040. Both 2040 and 2050 targets require a much deeper transformation of the energy system, through large scale deployment of climate-neutral technologies that require high investment efforts with some technologies not yet deployed at market scale. While some of the current instruments will keep delivering reductions well beyond 2030 (notably the EU ETS but also CO2 standards for vehicles, ReFuelEU Aviation, FuelEU Maritime and the Fluorinated gas (F-gas) Regulation), there will be a need to review, update and complete the legislative framework for the post-2030 period. This will include topics such as carbon capture, industrial carbon removals, and overall and sector specific emission reduction trajectories. In addition, larger emis- sion reductions in difficult-to-abate sectors like agriculture will be needed, along with a larger role for carbon removals, including utilising land as a carbon sink. | I9: Establishing the framework for achieving climate neutrality and amending regulations (EC) No 401/2009 and (EU) 2018/1999 ("European Climate Law")
B10: GHG Reduction | C10: #DDEBF7 | D10: TA1.7 | E10: =ISNUMBER(MATCH(D10,data!A:A)) -> TRUE | F10: =ISNUMBER(MATCH(D10,data!E:E)) -> TRUE | G10: Reduce methane emissions by 35 to 37% compared to 2005 levels, by 2030 | H10: Methane emissions were 497.15 MtCO2e in 2005 and decreased to 394.37 MtCO2e in 2022, making a reduction of about 20.67%. However, acceleration is needed to reach at least a 35% reduction by 2030. The largest source of methane emissions in the EU is the agriculture sector, accounting for more than half of the total emissions, followed by the energy and waste sectors. Within agriculture, almost all methane emissions are from livestock: 80% of the total stems from enteric fermentation and 18% from manure man- agement. Furthermore, the energy sector showed the highest decline in emissions, primarily due to the mitigation of fugitive emissions from fuels, including emis- sions from the extraction of solid fuels and those associated with oil and natural gas production and distribution. Most methane emissions from the waste sector come from solid waste disposal. GHG Emissions | I10: On an EU Strategy to reduce methane emissions
B11: Methane | C11: #DDEBF7 | D11: TA1.7 | E11: =ISNUMBER(MATCH(D11,data!A:A)) -> TRUE | F11: =ISNUMBER(MATCH(D11,data!E:E)) -> TRUE | G11: Reduce methane emissions by 35 to 37% compared to 2005 levels, by 2030 | H11: Methane emissions were 497.15 MtCO2e in 2005 and decreased to 394.37 MtCO2e in 2022, making a reduction of about 20.67%. However, acceleration is needed to reach at least a 35% reduction by 2030. The largest source of methane emissions in the EU is the agriculture sector, accounting for more than half of the total emissions, followed by the energy and waste sectors. Within agriculture, almost all methane emissions are from livestock: 80% of the total stems from enteric fermentation and 18% from manure man- agement. Furthermore, the energy sector showed the highest decline in emissions, primarily due to the mitigation of fugitive emissions from fuels, including emis- sions from the extraction of solid fuels and those associated with oil and natural gas production and distribution. Most methane emissions from the waste sector come from solid waste disposal. GHG Emissions | I11: On an EU Strategy to reduce methane emissions
B12: Energy Efficiency | C12: #DDEBF7 | D12: TA1.8 | E12: =ISNUMBER(MATCH(D12,data!A:A)) -> TRUE | F12: =ISNUMBER(MATCH(D12,data!E:E)) -> TRUE | G12: Reach energy neutrality in the wastewater treatment sector by 2045. | H12: There is a considerable potential for reducing fossil fuel-based energy use and GHG emissions in wastewater treatment and market incentives are increasingly attractive for investments in this direction. Member states should be required to ensure that the total annual energy used by all urban wastewater treatment plants on their territory treating a load of 10 000 population equivalent1 and above does not exceed the production of energy from renewable sources. 1 A number expressing the ratio of the sum of the pollution load in wastewater to the individual pollution load in household sewage produced by one person at the same time | I12: Concerning urban wastewater treatment (recast)
